<mujoco model="mobile">
  <compiler angle="radian" meshdir="../assets/"/>
  <statistic meansize="0.132335" extent="1.974" center="-0.11444 0.00208192 0.138066"/>
  <include file="scene.xml"/>
  <asset>
    <!-- robot_mesh -->
    <mesh name="base_link" file="base_link.STL"/>
    <mesh name="right_base_link" file="right_base_link.STL"/>
    <mesh name="right_link1" file="right_link1.STL"/>
    <mesh name="right_link2" file="right_link2.STL"/>
    <mesh name="right_link3" file="right_link3.STL"/>
    <mesh name="right_link4" file="right_link4.STL"/>
    <mesh name="right_link5" file="right_link5.STL"/>
    <mesh name="right_link6" file="right_link6.STL"/>
    <mesh name="left_base_link" file="left_base_link.STL"/>
    <mesh name="left_link1" file="left_link1.STL"/>
    <mesh name="left_link2" file="left_link2.STL"/>
    <mesh name="left_link3" file="left_link3.STL"/>
    <mesh name="left_link4" file="left_link4.STL"/>
    <mesh name="left_link5" file="left_link5.STL"/>
    <mesh name="left_link6" file="left_link6.STL"/>
    <!--robotiq-->
    <material name="metal" rgba="0.58 0.58 0.58 1"/>
    <material name="silicone" rgba="0.1882 0.1882 0.1882 1"/>
    <material name="gray" rgba="0.4627 0.4627 0.4627 1"/>
    <material name="black" rgba="0.149 0.149 0.149 1"/>

    <mesh class="2f85" file="base_mount.stl"/>
    <mesh class="2f85" file="base.stl"/>
    <mesh class="2f85" file="driver.stl"/>
    <mesh class="2f85" file="coupler.stl"/>
    <mesh class="2f85" file="follower.stl"/>
    <mesh class="2f85" file="pad.stl"/>
    <mesh class="2f85" file="silicone_pad.stl"/>
    <mesh class="2f85" file="spring_link.stl"/>
  </asset>

  <default>
    <default class="2f85">
      <mesh scale="0.001 0.001 0.001"/>
      <general biastype="affine"/>

      <joint axis="1 0 0"/>
      <default class="driver">
        <joint range="0 0.8" armature="0.005" damping="0.1" solimplimit="0.95 0.99 0.001" solreflimit="0.005 1"/>
      </default>
      <default class="follower">
        <joint range="-0.872664 0.872664" pos="0 -0.018 0.0065" solimplimit="0.95 0.99 0.001" solreflimit="0.005 1"/>
      </default>
      <default class="spring_link">
        <joint range="-0.29670597283 0.8" stiffness="0.05" springref="2.62" damping="0.00125"/>
      </default>
      <default class="coupler">
        <joint range="-1.57 0" solimplimit="0.95 0.99 0.001" solreflimit="0.005 1"/>
      </default>

      <default class="visual">
        <geom type="mesh" contype="0" conaffinity="0" group="2"/>
      </default>
      <default class="collision">
        <geom type="mesh" group="3"/>
        <default class="pad_box1">
<!--          修改1-->
          <geom mass="0" type="box" pos="0 -0.0026 0.028125" size="0.011 0.004 0.009375" friction="1.5 0.5 0.3"
            solimp="0.95 0.99 0.001" solref="0.004 1" priority="1" rgba="0.55 0.55 0.55 1"/>
        </default>
        <default class="pad_box2">
          <geom mass="0" type="box" pos="0 -0.0026 0.009375" size="0.011 0.004 0.009375" friction="1.5 0.5 0.3"
            solimp="0.95 0.99 0.001" solref="0.004 1" priority="1" rgba="0.45 0.45 0.45 1"/>
        </default>
      </default>
    </default>
  </default>

  <worldbody>
    <!-- robot -->
    <geom type="mesh" contype="0" conaffinity="0" group="1" density="0" rgba="1 1 1 1" mesh="base_link"/>
    <geom type="mesh" rgba="1 1 1 1" mesh="base_link"/>
    <geom type="mesh" contype="0" conaffinity="0" group="1" density="0" rgba="0.898039 0.917647 0.929412 1" mesh="right_base_link"/>
    <geom type="mesh" rgba="0.898039 0.917647 0.929412 1" mesh="right_base_link"/>
    <geom type="mesh" contype="0" conaffinity="0" group="1" density="0" rgba="0.898039 0.917647 0.929412 1" mesh="left_base_link"/>
    <geom type="mesh" rgba="0.898039 0.917647 0.929412 1" mesh="left_base_link"/>
    <body name="right_link1" pos="0.077 0.0005 0.43" quat="0.707107 0 0 0.707107">
      <inertial pos="-0.180507 -9.14459e-08 0.00955031" quat="0.43008 0.561259 0.561304 0.430067" mass="0.23233" diaginertia="0.000394134 0.000338875 0.000302877"/>
      <joint name="right_link1" pos="0 0 0" axis="1 0 0" range="-3.14 3.14" frictionloss="60"/>
      <geom type="mesh" contype="0" conaffinity="0" group="1" density="0" rgba="0.898039 0.917647 0.929412 1" mesh="right_link1"/>
      <geom type="mesh" rgba="0.898039 0.917647 0.929412 1" mesh="right_link1"/>
      <body name="right_link2" pos="-0.18185 0 0" quat="0.707105 0 0.707108 0">
        <inertial pos="-0.120187 1.57771e-06 -0.103646" quat="0.707172 0.00778026 0.00774997 0.706956" mass="0.502889" diaginertia="0.000546589 0.000532059 0.000573687"/>
        <joint name="right_link2" pos="0 0 0" axis="1 0 0" range="-3.14 3.14" frictionloss="60"/>
        <geom type="mesh" contype="0" conaffinity="0" group="1" density="0" rgba="0.898039 0.917647 0.929412 1" mesh="right_link2"/>
        <geom type="mesh" rgba="0.898039 0.917647 0.929412 1" mesh="right_link2"/>
        <body name="right_link3" pos="-0.11985 0 -0.24355">
          <inertial pos="0.0881412 3.46098e-07 -0.113366" quat="0.706566 -0.0276121 -0.0276147 0.706569" mass="0.239976" diaginertia="0.000183028 0.000179849 0.000152432"/>
          <joint name="right_link3" pos="0 0 0" axis="1 0 0" range="-3.14 3.14" frictionloss="60"/>
          <geom type="mesh" contype="0" conaffinity="0" group="1" density="0" rgba="0.898039 0.917647 0.929412 1" mesh="right_link3"/>
          <geom type="mesh" rgba="0.898039 0.917647 0.929412 1" mesh="right_link3"/>
          <body name="right_link4" pos="0.09285 0 -0.2132">
            <inertial pos="-0.0915543 -1.51027e-07 -3.97056e-05" quat="0.52054 0.478557 0.478585 0.520556" mass="0.10126" diaginertia="0.000111173 0.0000854587 0.0000777565"/>
            <joint name="right_link4" pos="0 0 0" axis="1 0 0" range="-3.14 3.14" frictionloss="60"/>
            <geom type="mesh" contype="0" conaffinity="0" group="1" density="0" rgba="0.898039 0.917647 0.929412 1" mesh="right_link4"/>
            <geom type="mesh" rgba="0.898039 0.917647 0.929412 1" mesh="right_link4"/>
            <body name="right_link5" pos="-0.10405 0 0">
              <inertial pos="-3.09303e-05 -4.5889e-08 -0.0800602" quat="0.508885 0.490953 0.49087 0.508968" mass="0.0855533" diaginertia="0.0000783986 0.0000700782 0.0000525718"/>
              <joint name="right_link5" pos="0 0 0" axis="0 0 1" range="-3.14 3.14" frictionloss="60"/>
              <geom type="mesh" contype="0" conaffinity="0" group="1" density="0" rgba="0.898039 0.917647 0.929412 1" mesh="right_link5"/>
              <geom type="mesh" rgba="0.898039 0.917647 0.929412 1" mesh="right_link5"/>
              <body name="right_link6" pos="0 0 -0.08535">
                <inertial pos="-0.0667479 2.16944e-08 0.000153725" quat="0.707249 0.706962 -0.00139353 0.00138544" mass="0.0394097" diaginertia="0.0000196561 0.0000171689 0.0000170178"/>
                <joint name="right_link6" pos="0 0 0" axis="1 0 0" range="-3.14 3.14" frictionloss="60"/>
                <geom type="mesh" contype="0" conaffinity="0" group="1" density="0" rgba="0.898039 0.917647 0.929412 1" mesh="right_link6"/>
                <geom type="mesh" rgba="0.898039 0.917647 0.929412 1" mesh="right_link6"/>
                  <include file="right_2f85.xml" />
              </body>
            </body>
          </body>
        </body>
      </body>
    </body>
    <body name="left_link1" pos="0.077 0.0005 0.43" quat="0.707107 0 0 0.707107">
      <inertial pos="0.180507 9.08564e-08 0.00955031" quat="0.561259 0.43008 0.430067 0.561304" mass="0.23233" diaginertia="0.000394134 0.000338875 0.000302877"/>
      <joint name="left_link1" pos="0 0 0" axis="-1 0 0" range="-3.14 3.14" frictionloss="60"/>
      <geom type="mesh" contype="0" conaffinity="0" group="1" density="0" rgba="0.898039 0.917647 0.929412 1" mesh="left_link1"/>
      <geom type="mesh" rgba="0.898039 0.917647 0.929412 1" mesh="left_link1"/>
      <body name="left_link2" pos="0.18185 0 0" quat="0.707107 0 0.707107 0">
        <inertial pos="-0.120187 -1.58623e-06 0.103646" quat="0.706956 -0.00774998 -0.00778026 0.707172" mass="0.502889" diaginertia="0.000546589 0.000532059 0.000573687"/>
        <joint name="left_link2" pos="0 0 0" axis="1 0 0" range="-3.14 3.14" frictionloss="60"/>
        <geom type="mesh" contype="0" conaffinity="0" group="1" density="0" rgba="0.898039 0.917647 0.929412 1" mesh="left_link2"/>
        <geom type="mesh" rgba="0.898039 0.917647 0.929412 1" mesh="left_link2"/>
        <body name="left_link3" pos="-0.11985 0 0.24355">
          <inertial pos="0.0881412 -3.41398e-07 0.113366" quat="0.706569 0.0276147 0.0276122 0.706566" mass="0.239976" diaginertia="0.000183028 0.000179849 0.000152432"/>
          <joint name="left_link3" pos="0 0 0" axis="-1 0 0" range="-3.14 3.14" frictionloss="60"/>
          <geom type="mesh" contype="0" conaffinity="0" group="1" density="0" rgba="0.898039 0.917647 0.929412 1" mesh="left_link3"/>
          <geom type="mesh" rgba="0.898039 0.917647 0.929412 1" mesh="left_link3"/>
          <body name="left_link4" pos="0.09285 0 0.2132">
            <inertial pos="-0.0915544 1.50835e-07 3.9706e-05" quat="0.478585 0.520556 0.52054 0.478557" mass="0.10126" diaginertia="0.000111173 0.0000854587 0.0000777565"/>
            <joint name="left_link4" pos="0 0 0" axis="1 0 0" range="-3.14 3.14" frictionloss="60"/>
            <geom type="mesh" contype="0" conaffinity="0" group="1" density="0" rgba="0.898039 0.917647 0.929412 1" mesh="left_link4"/>
            <geom type="mesh" rgba="0.898039 0.917647 0.929412 1" mesh="left_link4"/>
            <body name="left_link5" pos="-0.10405 0 0">
              <inertial pos="-3.09337e-05 6.7496e-08 0.0800602" quat="0.490869 0.508969 0.508885 0.490953" mass="0.0855533" diaginertia="0.0000783986 0.0000700782 0.0000525718"/>
              <joint name="left_link5" pos="0 0 0" axis="0 0 -1" range="-3.14 3.14" frictionloss="60"/>
              <geom type="mesh" contype="0" conaffinity="0" group="1" density="0" rgba="0.898039 0.917647 0.929412 1" mesh="left_link5"/>
              <geom type="mesh" rgba="0.898039 0.917647 0.929412 1" mesh="left_link5"/>
              <body name="left_link6" pos="0 0 0.08535">
                <inertial pos="-0.0667479 -2.16944e-08 -0.000153725" quat="0.707249 0.706962 0.00139353 -0.00138544" mass="0.0394097" diaginertia="0.0000196561 0.0000171689 0.0000170178"/>
                <joint name="left_link6" pos="0 0 0" axis="-1 0 0" range="-3.14 3.14" frictionloss="60"/>
                <geom type="mesh" contype="0" conaffinity="0" group="1" density="0" rgba="0.898039 0.917647 0.929412 1" mesh="left_link6"/>
                <geom type="mesh" rgba="0.898039 0.917647 0.929412 1" mesh="left_link6"/>
                  <include file="left_2f85.xml" />
              </body>
            </body>
          </body>
        </body>
      </body>
    </body>
    <!--   basket-->
    <body name="basket" pos="0.5 0 0.23" quat="1 0 0 0">
      <joint name="basket_joint" type="free" frictionloss="0.01" />
      <inertial pos="0 0 0" mass="0.02" diaginertia="0.002 0.002 0.002" />
      <geom name="mug_visual"   type="mesh" mesh="mug" rgba="0 0 0.7 1.0" contype="0" conaffinity="0"/>
      <geom name="mug_contact0" type="mesh" mesh="mug_contact0" rgba="0 0 0.7 1.0"/>
      <geom name="mug_contact1" type="mesh" mesh="mug_contact1" rgba="0 0 0.7 1.0"/>
      <geom name="mug_contact2" type="mesh" mesh="mug_contact2" rgba="0 0 0.7 1.0"/>
      <geom name="mug_contact3" type="mesh" mesh="mug_contact3" rgba="0 0 0.7 1.0"/>
      <geom name="mug_contact4" type="mesh" mesh="mug_contact4" rgba="0 0 0.7 1.0"/>
      <geom name="mug_contact5" type="mesh" mesh="mug_contact5" rgba="0 0 0.7 1.0"/>
      <geom name="mug_contact6" type="mesh" mesh="mug_contact6" rgba="0 0 0.7 1.0"/>
      <geom name="mug_contact7" type="mesh" mesh="mug_contact7" rgba="0 0 0.7 1.0"/>
      <geom name="mug_contact8" type="mesh" mesh="mug_contact8" rgba="0 0 0.7 1.0"/>
      <geom name="mug_contact9" type="mesh" mesh="mug_contact9" rgba="0 0 0.7 1.0"/>
      <geom name="mug_contact10" type="mesh" mesh="mug_contact10" rgba="0 0 0.7 1.0"/>
      <geom name="mug_contact11" type="mesh" mesh="mug_contact11" rgba="0 0 0.7 1.0"/>
      <geom name="mug_contact12" type="mesh" mesh="mug_contact12" rgba="0 0 0.7 1.0"/>
      <geom name="mug_contact13" type="mesh" mesh="mug_contact13" rgba="0 0 0.7 1.0"/>
    </body>
    <!--    hammer-->
    <body name="hammer" pos="0.375 0.2 0.13" quat="0 -0.7071 0.7071 0">
      <joint name="hammer_joint" type="free" frictionloss="0.01" />
      <inertial pos="0 0 0" mass="0.02" diaginertia="0.002 0.002 0.002" />
      <geom name="hammer_visual" type="mesh" mesh="hammer" rgba="1 0 0 0.0" contype="1" conaffinity="1"/>
      <geom name="hammer_contact0" type="mesh" mesh="hammer_contact0" rgba="0.73 0.5 0.39 1" contype="0" conaffinity="0"/>
      <geom name="hammer_contact1" type="mesh" mesh="hammer_contact1" rgba="1 1 1 1" contype="0" conaffinity="0"/>
    </body>
    <!--    相机-->
    <body name="camera" pos="0.475 0.3 0.14" quat="1 0 -0. 0">
      <joint name="camera_joint" type="free" frictionloss="0.01" />
      <inertial pos="0 0 0" mass="0.02" diaginertia="0.002 0.002 0.002" />
      <geom name="camera_visual" type="mesh" mesh="camera" rgba="0.25 0.25 0.25 1" contype="1" conaffinity="1"/>
      <geom name="camera_contact0" type="mesh" mesh="camera_contact0" rgba="0.25 0.25 0.25 1" contype="0" conaffinity="0"/>
      <geom name="camera_contact1" type="mesh" mesh="camera_contact1" rgba="0.25 0.25 0.25 1" contype="0" conaffinity="0"/>
    </body>
    <!--    绿色订书机-->
    <body name="green_stapler" pos="0.375 0.3 0.14" quat="1 0 0 0">
      <joint name="green_stapler_joint" type="free" frictionloss="0.01" />
      <inertial pos="0 0 0" mass="0.02" diaginertia="0.002 0.002 0.002" />
      <geom name="green_stapler_visual" mesh="stapler" rgba="1 0 0 0.0" contype="1" conaffinity="1"/>
      <geom name="green_stapler_contact0" mesh="stapler_contact0" type="mesh" contype="0" conaffinity="0"/>
      <geom name="green_stapler_contact1" mesh="stapler_contact1" type="mesh" contype="0" conaffinity="0" rgba="0 1 1 0" />
      <geom name="green_stapler_contact2" mesh="stapler_contact2" type="mesh" contype="0" conaffinity="0" rgba="0.8 0.8 0.8 1" />
      <geom name="green_stapler_contact3" mesh="stapler_contact3" type="mesh" contype="0" conaffinity="0" rgba="0 1 0 1" />
      <geom name="green_stapler_contact4" mesh="stapler_contact4" type="mesh" contype="0" conaffinity="0" rgba="0 1 0 1" />
    </body>
    <!--  黑色订书机-->
    <body name="black_stapler" pos="0.475 0.2 0.14" quat="0.5 0.5 0.5 0.5">
      <joint name="black_stapler_joint" type="free" frictionloss="0.01" />
      <inertial pos="0 0 0" mass="0.02" diaginertia="0.002 0.002 0.002" />
      <geom name="black_stapler_visual" mesh="stapler" rgba="1 0 0 0.0" contype="1" conaffinity="1"/>
      <geom name="black_stapler_contact0" mesh="stapler_contact0" type="mesh" contype="0" conaffinity="0"/>
      <geom name="black_stapler_contact1" mesh="stapler_contact1" type="mesh" rgba="0 1 1 0" contype="0" conaffinity="0"/>
      <geom name="black_stapler_contact2" mesh="stapler_contact2" type="mesh" rgba="0.8 0.8 0.8 1" contype="0" conaffinity="0"/>
      <geom name="black_stapler_contact3" mesh="stapler_contact3" type="mesh" rgba="0.2 0.2 0.2 1" contype="0" conaffinity="0"/>
      <geom name="black_stapler_contact4" mesh="stapler_contact4" type="mesh" rgba="0.2 0.2 0.2 1" contype="0" conaffinity="0"/>
    </body>

  </worldbody>
  <contact>
    <!--left-hand-->
    <exclude body1="left-hand_base" body2="left-hand_left_driver"/>
    <exclude body1="left-hand_base" body2="left-hand_right_driver"/>
    <exclude body1="left-hand_base" body2="left-hand_left_spring_link"/>
    <exclude body1="left-hand_base" body2="left-hand_right_spring_link"/>
    <exclude body1="left-hand_right_coupler" body2="left-hand_right_follower"/>
    <exclude body1="left-hand_left_coupler" body2="left-hand_left_follower"/>
    <!--right-hand-->
    <exclude body1="right-hand_base" body2="right-hand_left_driver"/>
    <exclude body1="right-hand_base" body2="right-hand_right_driver"/>
    <exclude body1="right-hand_base" body2="right-hand_left_spring_link"/>
    <exclude body1="right-hand_base" body2="right-hand_right_spring_link"/>
    <exclude body1="right-hand_right_coupler" body2="right-hand_right_follower"/>
    <exclude body1="right-hand_left_coupler" body2="right-hand_left_follower"/>

  </contact>

  <!--
    This adds stability to the model by having a tendon that distributes the forces between both
    joints, such that the equality constraint doesn't have to do that much work in order to equalize
    both joints. Since both joints share the same sign, we split the force between both equally by
    setting coef=0.5
  -->
  <tendon>
    <fixed name="right-hand_split">
      <joint joint="right-hand_right_driver_joint" coef="0.5"/>
      <joint joint="right-hand_left_driver_joint" coef="0.5"/>
    </fixed>
    <fixed name="left-hand_split">
      <joint joint="left-hand_right_driver_joint" coef="0.5"/>
      <joint joint="left-hand_left_driver_joint" coef="0.5"/>
    </fixed>
  </tendon>

  <equality>
    <connect anchor="0 0 0" body1="left-hand_right_follower" body2="left-hand_right_coupler" solimp="0.95 0.99 0.001" solref="0.005 1"/>
    <connect anchor="0 0 0" body1="left-hand_left_follower" body2="left-hand_left_coupler" solimp="0.95 0.99 0.001" solref="0.005 1"/>
    <joint joint1="left-hand_right_driver_joint" joint2="left-hand_left_driver_joint" polycoef="0 1 0 0 0" solimp="0.95 0.99 0.001"
      solref="0.005 1"/>
    <connect anchor="0 0 0" body1="right-hand_right_follower" body2="right-hand_right_coupler" solimp="0.95 0.99 0.001" solref="0.005 1"/>
    <connect anchor="0 0 0" body1="right-hand_left_follower" body2="right-hand_left_coupler" solimp="0.95 0.99 0.001" solref="0.005 1"/>
    <joint joint1="right-hand_right_driver_joint" joint2="right-hand_left_driver_joint" polycoef="0 1 0 0 0" solimp="0.95 0.99 0.001"
      solref="0.005 1"/>

  </equality>

  <!--
    The general actuator below is a customized position actuator (with some damping) where
    gainprm[0] != kp (see http://mujoco.org/book/modeling.html#position).
    The reason why gainprm[0] != kp is because the control input range has to be re-scaled to
    [0, 255]. The joint range is currently set at [0, 0.8], the control range is [0, 255] and
    kp = 100. Tau = Kp * scale * control_input - Kp * error, max(Kp * scale * control_input) = 0.8,
    hence scale = 0.8 * 100 / 255
  -->
  <actuator>
    <position ctrllimited="true" ctrlrange="-3.14158 3.14158" name="left_joint1" joint="left_link1" kp="10000"  user="1"/>
    <position ctrllimited="true" ctrlrange="-3.14158 3.14158" name="left_joint2" joint="left_link2" kp="800"  user="1"/>
    <position ctrllimited="true" ctrlrange="-3.14158 3.14158" name="left_joint3" joint="left_link3" kp="100"  user="1"/>
    <position ctrllimited="true" ctrlrange="-3.14158 3.14158" name="left_joint4" joint="left_link4" kp="50"  user="1"/>
    <position ctrllimited="true" ctrlrange="-3.14158 3.14158" name="left_joint5" joint="left_link5" kp="40"  user="1"/>
    <position ctrllimited="true" ctrlrange="-3.14158 3.14158" name="left_joint6" joint="left_link6" kp="10"  user="1"/>
    <general class="2f85" name="left-hand_fingers_actuator" tendon="left-hand_split" forcerange="-5 5" ctrlrange="0 255"
      gainprm="0.3137255 0 0" biasprm="0 -100 -10"/>
    <position ctrllimited="true" ctrlrange="-3.14158 3.14158" name="right_joint1" joint="right_link1" kp="10000"  user="1"/>
    <position ctrllimited="true" ctrlrange="-3.14158 3.14158" name="right_joint2" joint="right_link2" kp="800"  user="1"/>
    <position ctrllimited="true" ctrlrange="-3.14158 3.14158" name="right_joint3" joint="right_link3" kp="100"  user="1"/>
    <position ctrllimited="true" ctrlrange="-3.14158 3.14158" name="right_joint4" joint="right_link4" kp="50"  user="1"/>
    <position ctrllimited="true" ctrlrange="-3.14158 3.14158" name="right_joint5" joint="right_link5" kp="40"  user="1"/>
    <position ctrllimited="true" ctrlrange="-3.14158 3.14158" name="right_joint6" joint="right_link6" kp="10"  user="1"/>
    <general class="2f85" name="right-hand_fingers_actuator" tendon="right-hand_split" forcerange="-5 5" ctrlrange="0 255"
      gainprm="0.3137255 0 0" biasprm="0 -100 -10"/>
  </actuator>


</mujoco>
