<mujocoinclude>
  <asset>
    <mesh name="original-62.obj.convex" file="original-62.obj.convex.stl"/>
    <mesh name="original-54.obj.convex" file="original-54.obj.convex.stl"/>
    <mesh name="original-58.obj.convex" file="original-58.obj.convex.stl"/>
    <mesh name="original-53.obj.convex" file="original-53.obj.convex.stl"/>
    <mesh name="original-59.obj.convex" file="original-59.obj.convex.stl"/>
    <mesh name="original-57.obj.convex" file="original-57.obj.convex.stl"/>
    <mesh name="original-56.obj.convex" file="original-56.obj.convex.stl"/>
    <mesh name="original-63.obj.convex" file="original-63.obj.convex.stl"/>
    <mesh name="original-49.obj.convex" file="original-49.obj.convex.stl"/>
    <mesh name="original-41.obj.convex" file="original-41.obj.convex.stl"/>
    <mesh name="original-45.obj.convex" file="original-45.obj.convex.stl"/>
    <mesh name="original-40.obj.convex" file="original-40.obj.convex.stl"/>
    <mesh name="original-46.obj.convex" file="original-46.obj.convex.stl"/>
    <mesh name="original-43.obj.convex" file="original-43.obj.convex.stl"/>
    <mesh name="original-44.obj.convex" file="original-44.obj.convex.stl"/>
    <mesh name="original-50.obj.convex" file="original-50.obj.convex.stl"/>
    <mesh name="original-28.obj.convex" file="original-28.obj.convex.stl"/>
    <mesh name="original-36.obj.convex" file="original-36.obj.convex.stl"/>
    <mesh name="original-32.obj.convex" file="original-32.obj.convex.stl"/>
    <mesh name="original-27.obj.convex" file="original-27.obj.convex.stl"/>
    <mesh name="original-33.obj.convex" file="original-33.obj.convex.stl"/>
    <mesh name="original-31.obj.convex" file="original-31.obj.convex.stl"/>
    <mesh name="original-30.obj.convex" file="original-30.obj.convex.stl"/>
    <mesh name="original-37.obj.convex" file="original-37.obj.convex.stl"/>
    <mesh name="original-3.obj.convex" file="original-3.obj.convex.stl"/>
    <mesh name="original-7.obj.convex" file="original-7.obj.convex.stl"/>
    <mesh name="original-4.obj.convex" file="original-4.obj.convex.stl"/>
    <mesh name="original-8.obj.convex" file="original-8.obj.convex.stl"/>
    <mesh name="original-24.obj.convex" file="original-24.obj.convex.stl"/>
    <mesh name="original-17.obj.convex" file="original-17.obj.convex.stl"/>
    <mesh name="original-6.obj.convex" file="original-6.obj.convex.stl"/>
    <mesh name="original-22.obj.convex" file="original-22.obj.convex.stl"/>
    <mesh name="original-21.obj.convex" file="original-21.obj.convex.stl"/>
    <mesh name="original-23.obj.convex" file="original-23.obj.convex.stl"/>
    <mesh name="original-20.obj.convex" file="original-20.obj.convex.stl"/>
    <mesh name="original-15.obj.convex" file="original-15.obj.convex.stl"/>
    <mesh name="original-14.obj.convex" file="original-14.obj.convex.stl"/>
    <mesh name="original-10.obj.convex" file="original-10.obj.convex.stl"/>
    <mesh name="original-11.obj.convex" file="original-11.obj.convex.stl"/>
    <mesh name="original-5.obj.convex" file="original-5.obj.convex.stl"/>
    <mesh name="original-2.obj.convex" file="original-2.obj.convex.stl"/>
    <mesh name="original-64.obj.convex" file="original-64.obj.convex.stl"/>
    <mesh name="original-60.obj.convex" file="original-60.obj.convex.stl"/>
    <mesh name="original-47.obj.convex" file="original-47.obj.convex.stl"/>
    <mesh name="original-34.obj.convex" file="original-34.obj.convex.stl"/>
    <mesh name="original-12.obj.convex" file="original-12.obj.convex.stl"/>
    <mesh name="original-18.obj.convex" file="original-18.obj.convex.stl"/>
    <mesh name="original-16.obj.convex" file="original-16.obj.convex.stl"/>
    <mesh name="original-19.obj.convex" file="original-19.obj.convex.stl"/>
  </asset>
  <worldbody>
    <geom name="frame_vertical_bar-38" quat="0.5 0.5 -0.5 -0.5" type="mesh" contype="0" conaffinity="0" group="1" density="0" mesh="original-3.obj.convex"/>
    <geom name="frame_vertical_bar-39" quat="0.5 0.5 -0.5 -0.5" type="mesh" contype="0" conaffinity="0" group="1" density="0" mesh="original-7.obj.convex"/>
    <geom name="frame_horizontal_bar-40" quat="0.5 0.5 -0.5 -0.5" type="mesh" contype="0" conaffinity="0" group="1" density="0" mesh="original-4.obj.convex"/>
    <geom name="frame_horizontal_bar-41" quat="0.5 0.5 -0.5 -0.5" type="mesh" contype="0" conaffinity="0" group="1" density="0" mesh="original-8.obj.convex"/>
    <geom name="frame_horizontal_bar-42" quat="0.5 0.5 -0.5 -0.5" type="mesh" contype="0" conaffinity="0" group="1" density="0" mesh="original-24.obj.convex"/>
    <geom name="frame_horizontal_bar-43" quat="0.5 0.5 -0.5 -0.5" type="mesh" contype="0" conaffinity="0" group="1" density="0" mesh="original-17.obj.convex"/>
    <geom name="frame_horizontal_bar-44" quat="0.5 0.5 -0.5 -0.5" type="mesh" contype="0" conaffinity="0" group="1" density="0" mesh="original-6.obj.convex"/>
    <geom name="other_leaf-52" pos="0 0 0" quat="0.5 0.5 -0.5 -0.5" type="mesh" contype="0" conaffinity="0" group="1" density="0" mesh="original-22.obj.convex"/>
    <geom name="other_leaf-51" quat="0.5 0.5 -0.5 -0.5" type="mesh" contype="0" conaffinity="0" group="1" density="0" mesh="original-21.obj.convex"/>
    <geom name="other_leaf-50" quat="0.5 0.5 -0.5 -0.5" type="mesh" contype="0" conaffinity="0" group="1" density="0" mesh="original-23.obj.convex"/>
    <geom name="other_leaf-49" quat="0.5 0.5 -0.5 -0.5" type="mesh" contype="0" conaffinity="0" group="1" density="0" mesh="original-20.obj.convex"/>
    <geom name="vertical_side_panel-53" quat="0.5 0.5 -0.5 -0.5" type="mesh" contype="0" conaffinity="0" group="1" density="0" mesh="original-15.obj.convex"/>
    <geom quat="0.5 0.5 -0.5 -0.5" type="mesh" contype="0" conaffinity="0" group="1" density="0" mesh="original-14.obj.convex"/>
    <geom name="vertical_side_panel-54" quat="0.5 0.5 -0.5 -0.5" type="mesh" contype="0" conaffinity="0" group="1" density="0" mesh="original-10.obj.convex"/>
    <geom quat="0.5 0.5 -0.5 -0.5" type="mesh" contype="0" conaffinity="0" group="1" density="0" mesh="original-11.obj.convex"/>
    <geom name="back_panel-55" quat="0.5 0.5 -0.5 -0.5" type="mesh" contype="0" conaffinity="0" group="1" density="0" mesh="original-5.obj.convex"/>
    <geom name="bottom_panel-56" quat="0.5 0.5 -0.5 -0.5" type="mesh" contype="0" conaffinity="0" group="1" density="0" mesh="original-2.obj.convex"/>
    <geom name="other_leaf-64" quat="0.5 0.5 -0.5 -0.5" type="mesh" contype="0" conaffinity="0" group="1" density="0" mesh="original-64.obj.convex"/>
    <geom name="other_leaf-63" quat="0.5 0.5 -0.5 -0.5" type="mesh" contype="0" conaffinity="0" group="1" density="0" mesh="original-60.obj.convex"/>
    <geom name="other_leaf-62" quat="0.5 0.5 -0.5 -0.5" type="mesh" contype="0" conaffinity="0" group="1" density="0" mesh="original-47.obj.convex"/>
    <geom name="other_leaf-61" quat="0.5 0.5 -0.5 -0.5" type="mesh" contype="0" conaffinity="0" group="1" density="0" mesh="original-34.obj.convex"/>
    <geom name="base_side_panel-29" quat="0.5 0.5 -0.5 -0.5" type="mesh" contype="0" conaffinity="0" group="1" density="0" mesh="original-12.obj.convex"/>
    <geom name="base_side_panel-30" quat="0.5 0.5 -0.5 -0.5" type="mesh" contype="0" conaffinity="0" group="1" density="0" mesh="original-18.obj.convex"/>
    <geom name="base_side_panel-31" quat="0.5 0.5 -0.5 -0.5" type="mesh" contype="0" conaffinity="0" group="1" density="0" mesh="original-16.obj.convex"/>
    <geom name="base_side_panel-32" quat="0.5 0.5 -0.5 -0.5" type="mesh" contype="0" conaffinity="0" group="1" density="0" mesh="original-19.obj.convex"/>
    <geom quat="0.5 0.5 -0.5 -0.5" type="mesh" mesh="original-3.obj.convex"/>
    <geom quat="0.5 0.5 -0.5 -0.5" type="mesh" mesh="original-7.obj.convex"/>
    <geom quat="0.5 0.5 -0.5 -0.5" type="mesh" mesh="original-4.obj.convex"/>
    <geom quat="0.5 0.5 -0.5 -0.5" type="mesh" mesh="original-8.obj.convex"/>
    <geom quat="0.5 0.5 -0.5 -0.5" type="mesh" mesh="original-24.obj.convex"/>
    <geom quat="0.5 0.5 -0.5 -0.5" type="mesh" mesh="original-17.obj.convex"/>
    <geom quat="0.5 0.5 -0.5 -0.5" type="mesh" mesh="original-6.obj.convex"/>
    <geom pos="0 0 0" quat="0.5 0.5 -0.5 -0.5" type="mesh" mesh="original-22.obj.convex"/>
    <geom quat="0.5 0.5 -0.5 -0.5" type="mesh" mesh="original-21.obj.convex"/>
    <geom quat="0.5 0.5 -0.5 -0.5" type="mesh" mesh="original-23.obj.convex"/>
    <geom quat="0.5 0.5 -0.5 -0.5" type="mesh" mesh="original-20.obj.convex"/>
    <geom quat="0.5 0.5 -0.5 -0.5" type="mesh" mesh="original-15.obj.convex"/>
    <geom quat="0.5 0.5 -0.5 -0.5" type="mesh" mesh="original-14.obj.convex"/>
    <geom quat="0.5 0.5 -0.5 -0.5" type="mesh" mesh="original-10.obj.convex"/>
    <geom quat="0.5 0.5 -0.5 -0.5" type="mesh" mesh="original-11.obj.convex"/>
    <geom quat="0.5 0.5 -0.5 -0.5" type="mesh" mesh="original-5.obj.convex"/>
    <geom quat="0.5 0.5 -0.5 -0.5" type="mesh" mesh="original-2.obj.convex"/>
    <geom quat="0.5 0.5 -0.5 -0.5" type="mesh" mesh="original-64.obj.convex"/>
    <geom quat="0.5 0.5 -0.5 -0.5" type="mesh" mesh="original-60.obj.convex"/>
    <geom quat="0.5 0.5 -0.5 -0.5" type="mesh" mesh="original-47.obj.convex"/>
    <geom quat="0.5 0.5 -0.5 -0.5" type="mesh" mesh="original-34.obj.convex"/>
    <geom quat="0.5 0.5 -0.5 -0.5" type="mesh" mesh="original-12.obj.convex"/>
    <geom quat="0.5 0.5 -0.5 -0.5" type="mesh" mesh="original-18.obj.convex"/>
    <geom quat="0.5 0.5 -0.5 -0.5" type="mesh" mesh="original-16.obj.convex"/>
    <geom quat="0.5 0.5 -0.5 -0.5" type="mesh" mesh="original-19.obj.convex"/>
    <body name="link_0" quat="0.5 0.5 -0.5 -0.5">
      <joint name="joint_0" pos="0 0 0" axis="0 0 1" type="slide" range="0 0.8"/>
      <geom name="drawer_front-23" type="mesh" contype="0" conaffinity="0" group="1" density="0" mesh="original-62.obj.convex"/>
      <geom type="mesh" contype="0" conaffinity="0" group="1" density="0" mesh="original-54.obj.convex"/>
      <geom name="drawer_side-24" type="mesh" contype="0" conaffinity="0" group="1" density="0" mesh="original-58.obj.convex"/>
      <geom name="drawer_side-25" type="mesh" contype="0" conaffinity="0" group="1" density="0" mesh="original-53.obj.convex"/>
      <geom name="drawer_back-26" type="mesh" contype="0" conaffinity="0" group="1" density="0" mesh="original-59.obj.convex"/>
      <geom name="drawer_bottom-27" type="mesh" contype="0" conaffinity="0" group="1" density="0" mesh="original-57.obj.convex"/>
      <geom type="mesh" contype="0" conaffinity="0" group="1" density="0" mesh="original-56.obj.convex"/>
      <geom name="handle-22" type="mesh" contype="0" conaffinity="0" group="1" density="0" mesh="original-63.obj.convex"/>
      <geom type="mesh" mesh="original-62.obj.convex"/>
      <geom type="mesh" mesh="original-54.obj.convex"/>
      <geom type="mesh" mesh="original-58.obj.convex"/>
      <geom type="mesh" mesh="original-53.obj.convex"/>
      <geom type="mesh" mesh="original-59.obj.convex"/>
      <geom type="mesh" mesh="original-57.obj.convex"/>
      <geom type="mesh" mesh="original-56.obj.convex"/>
      <geom type="mesh" mesh="original-63.obj.convex"/>
    </body>
    <body name="link_1" quat="0.5 0.5 -0.5 -0.5">
      <joint name="joint_1" pos="0 0 0" axis="0 0 1" type="slide" range="0 0.8"/>
      <geom name="drawer_front-16" type="mesh" contype="0" conaffinity="0" group="1" density="0" mesh="original-49.obj.convex"/>
      <geom type="mesh" contype="0" conaffinity="0" group="1" density="0" mesh="original-41.obj.convex"/>
      <geom name="drawer_side-17" type="mesh" contype="0" conaffinity="0" group="1" density="0" mesh="original-45.obj.convex"/>
      <geom name="drawer_side-18" type="mesh" contype="0" conaffinity="0" group="1" density="0" mesh="original-40.obj.convex"/>
      <geom name="drawer_back-19" type="mesh" contype="0" conaffinity="0" group="1" density="0" mesh="original-46.obj.convex"/>
      <geom name="drawer_bottom-20" type="mesh" contype="0" conaffinity="0" group="1" density="0" mesh="original-43.obj.convex"/>
      <geom type="mesh" contype="0" conaffinity="0" group="1" density="0" mesh="original-44.obj.convex"/>
      <geom name="handle-15" type="mesh" contype="0" conaffinity="0" group="1" density="0" mesh="original-50.obj.convex"/>
      <geom type="mesh" mesh="original-49.obj.convex"/>
      <geom type="mesh" mesh="original-41.obj.convex"/>
      <geom type="mesh" mesh="original-45.obj.convex"/>
      <geom type="mesh" mesh="original-40.obj.convex"/>
      <geom type="mesh" mesh="original-46.obj.convex"/>
      <geom type="mesh" mesh="original-43.obj.convex"/>
      <geom type="mesh" mesh="original-44.obj.convex"/>
      <geom type="mesh" mesh="original-50.obj.convex"/>
    </body>
    <body name="link_2" quat="0.5 0.5 -0.5 -0.5">
      <joint name="joint_2" pos="0 0 0" axis="0 0 1" type="slide" range="0 0.8"/>
      <geom name="drawer_front-9" type="mesh" contype="0" conaffinity="0" group="1" density="0" mesh="original-28.obj.convex"/>
      <geom type="mesh" contype="0" conaffinity="0" group="1" density="0" mesh="original-36.obj.convex"/>
      <geom name="drawer_side-10" type="mesh" contype="0" conaffinity="0" group="1" density="0" mesh="original-32.obj.convex"/>
      <geom name="drawer_side-11" type="mesh" contype="0" conaffinity="0" group="1" density="0" mesh="original-27.obj.convex"/>
      <geom name="drawer_back-12" type="mesh" contype="0" conaffinity="0" group="1" density="0" mesh="original-33.obj.convex"/>
      <geom name="drawer_bottom-13" type="mesh" contype="0" conaffinity="0" group="1" density="0" mesh="original-31.obj.convex"/>
      <geom type="mesh" contype="0" conaffinity="0" group="1" density="0" mesh="original-30.obj.convex"/>
      <geom name="handle-8" type="mesh" contype="0" conaffinity="0" group="1" density="0" mesh="original-37.obj.convex"/>
      <geom type="mesh" mesh="original-28.obj.convex"/>
      <geom type="mesh" mesh="original-36.obj.convex"/>
      <geom type="mesh" mesh="original-32.obj.convex"/>
      <geom type="mesh" mesh="original-27.obj.convex"/>
      <geom type="mesh" mesh="original-33.obj.convex"/>
      <geom type="mesh" mesh="original-31.obj.convex"/>
      <geom type="mesh" mesh="original-30.obj.convex"/>
      <geom type="mesh" mesh="original-37.obj.convex"/>
    </body>
  </worldbody>
<mujocoinclude>
